2025-07-31 20:30:39,675 INFO    Thread-30 (_run_job):23820 [wandb_setup.py:_flush():80] Current SDK version is 0.21.0
2025-07-31 20:30:39,676 INFO    Thread-30 (_run_job):23820 [wandb_setup.py:_flush():80] Configure stats pid to 23820
2025-07-31 20:30:39,676 INFO    Thread-30 (_run_job):23820 [wandb_setup.py:_flush():80] Loading settings from C:\Users\tobys\.config\wandb\settings
2025-07-31 20:30:39,676 INFO    Thread-30 (_run_job):23820 [wandb_setup.py:_flush():80] Loading settings from c:\Users\tobys\Downloads\GBM-ML-main\GBM-ML-main\wandb\settings
2025-07-31 20:30:39,676 INFO    Thread-30 (_run_job):23820 [wandb_setup.py:_flush():80] Loading settings from environment variables
2025-07-31 20:30:39,676 INFO    Thread-30 (_run_job):23820 [wandb_init.py:setup_run_log_directory():703] Logging user logs to c:\Users\tobys\Downloads\GBM-ML-main\GBM-ML-main\wandb\run-20250731_203039-moxifvda\logs\debug.log
2025-07-31 20:30:39,676 INFO    Thread-30 (_run_job):23820 [wandb_init.py:setup_run_log_directory():704] Logging internal logs to c:\Users\tobys\Downloads\GBM-ML-main\GBM-ML-main\wandb\run-20250731_203039-moxifvda\logs\debug-internal.log
2025-07-31 20:30:39,676 INFO    Thread-30 (_run_job):23820 [wandb_init.py:monkeypatch_ipython():622] configuring jupyter hooks <wandb.sdk.wandb_init._WandbInit object at 0x000001DB0DC3F940>
2025-07-31 20:30:39,677 INFO    Thread-30 (_run_job):23820 [wandb_init.py:init():830] calling init triggers
2025-07-31 20:30:39,677 INFO    Thread-30 (_run_job):23820 [wandb_init.py:init():835] wandb.init called with sweep_config: {'batch_size': 16, 'dropout': 0.1, 'learning_rate': 0.008375682299464123, 'model_dim': 32, 'num_epochs': 50, 'num_heads': 4, 'num_layers': 2, 'reduced_dim': 1024}
config: {'_wandb': {}}
2025-07-31 20:30:39,677 INFO    Thread-30 (_run_job):23820 [wandb_init.py:init():871] starting backend
2025-07-31 20:30:39,910 INFO    Thread-30 (_run_job):23820 [wandb_init.py:init():874] sending inform_init request
2025-07-31 20:30:39,913 INFO    Thread-30 (_run_job):23820 [wandb_init.py:init():882] backend started and connected
2025-07-31 20:30:39,916 INFO    Thread-30 (_run_job):23820 [wandb_run.py:_config_callback():1363] config_cb None None {'batch_size': 16, 'dropout': 0.1, 'learning_rate': 0.008375682299464123, 'model_dim': 32, 'num_epochs': 50, 'num_heads': 4, 'num_layers': 2, 'reduced_dim': 1024}
2025-07-31 20:30:39,917 INFO    Thread-30 (_run_job):23820 [wandb_run.py:_label_probe_notebook():1304] probe notebook
2025-07-31 20:30:39,918 INFO    Thread-30 (_run_job):23820 [wandb_init.py:init():953] updated telemetry
2025-07-31 20:30:39,920 INFO    Thread-30 (_run_job):23820 [wandb_init.py:init():977] communicating run to backend with 90.0 second timeout
2025-07-31 20:30:40,300 INFO    Thread-30 (_run_job):23820 [wandb_init.py:init():1029] starting run threads in backend
2025-07-31 20:30:40,500 INFO    Thread-30 (_run_job):23820 [wandb_run.py:_console_start():2458] atexit reg
2025-07-31 20:30:40,501 INFO    Thread-30 (_run_job):23820 [wandb_run.py:_redirect():2306] redirect: wrap_raw
2025-07-31 20:30:40,501 INFO    Thread-30 (_run_job):23820 [wandb_run.py:_redirect():2375] Wrapping output streams.
2025-07-31 20:30:40,501 INFO    Thread-30 (_run_job):23820 [wandb_run.py:_redirect():2398] Redirects installed.
2025-07-31 20:30:40,501 INFO    Thread-30 (_run_job):23820 [wandb_init.py:init():1075] run started, returning control to user process
2025-07-31 23:44:36,378 INFO    Thread-29 (_heartbeat):23820 [retry.py:__call__():173] [no run ID] Retry attempt failed:
Traceback (most recent call last):
  File "C:\Users\tobys\AppData\Roaming\Python\Python310\site-packages\urllib3\connection.py", line 198, in _new_conn
    sock = connection.create_connection(
  File "C:\Users\tobys\AppData\Roaming\Python\Python310\site-packages\urllib3\util\connection.py", line 60, in create_connection
    for res in socket.getaddrinfo(host, port, family, socket.SOCK_STREAM):
  File "c:\Users\tobys\anaconda3\envs\star-pinn\lib\socket.py", line 967, in getaddrinfo
    for res in _socket.getaddrinfo(host, port, family, type, proto, flags):
socket.gaierror: [Errno 11001] getaddrinfo failed

The above exception was the direct cause of the following exception:

Traceback (most recent call last):
  File "C:\Users\tobys\AppData\Roaming\Python\Python310\site-packages\urllib3\connectionpool.py", line 787, in urlopen
    response = self._make_request(
  File "C:\Users\tobys\AppData\Roaming\Python\Python310\site-packages\urllib3\connectionpool.py", line 488, in _make_request
    raise new_e
  File "C:\Users\tobys\AppData\Roaming\Python\Python310\site-packages\urllib3\connectionpool.py", line 464, in _make_request
    self._validate_conn(conn)
  File "C:\Users\tobys\AppData\Roaming\Python\Python310\site-packages\urllib3\connectionpool.py", line 1093, in _validate_conn
    conn.connect()
  File "C:\Users\tobys\AppData\Roaming\Python\Python310\site-packages\urllib3\connection.py", line 704, in connect
    self.sock = sock = self._new_conn()
  File "C:\Users\tobys\AppData\Roaming\Python\Python310\site-packages\urllib3\connection.py", line 205, in _new_conn
    raise NameResolutionError(self.host, self, e) from e
urllib3.exceptions.NameResolutionError: <urllib3.connection.HTTPSConnection object at 0x000001DB0DC46680>: Failed to resolve 'api.wandb.ai' ([Errno 11001] getaddrinfo failed)

The above exception was the direct cause of the following exception:

Traceback (most recent call last):
  File "C:\Users\tobys\AppData\Roaming\Python\Python310\site-packages\requests\adapters.py", line 667, in send
    resp = conn.urlopen(
  File "C:\Users\tobys\AppData\Roaming\Python\Python310\site-packages\urllib3\connectionpool.py", line 841, in urlopen
    retries = retries.increment(
  File "C:\Users\tobys\AppData\Roaming\Python\Python310\site-packages\urllib3\util\retry.py", line 519, in increment
    raise MaxRetryError(_pool, url, reason) from reason  # type: ignore[arg-type]
urllib3.exceptions.MaxRetryError: HTTPSConnectionPool(host='api.wandb.ai', port=443): Max retries exceeded with url: /graphql (Caused by NameResolutionError("<urllib3.connection.HTTPSConnection object at 0x000001DB0DC46680>: Failed to resolve 'api.wandb.ai' ([Errno 11001] getaddrinfo failed)"))

During handling of the above exception, another exception occurred:

Traceback (most recent call last):
  File "c:\Users\tobys\anaconda3\envs\star-pinn\lib\site-packages\wandb\sdk\lib\retry.py", line 134, in __call__
    result = self._call_fn(*args, **kwargs)
  File "c:\Users\tobys\anaconda3\envs\star-pinn\lib\site-packages\wandb\sdk\internal\internal_api.py", line 397, in execute
    return self.client.execute(*args, **kwargs)  # type: ignore
  File "c:\Users\tobys\anaconda3\envs\star-pinn\lib\site-packages\wandb\vendor\gql-0.2.0\wandb_gql\client.py", line 52, in execute
    result = self._get_result(document, *args, **kwargs)
  File "c:\Users\tobys\anaconda3\envs\star-pinn\lib\site-packages\wandb\vendor\gql-0.2.0\wandb_gql\client.py", line 60, in _get_result
    return self.transport.execute(document, *args, **kwargs)
  File "c:\Users\tobys\anaconda3\envs\star-pinn\lib\site-packages\wandb\sdk\lib\gql_request.py", line 58, in execute
    request = self.session.post(self.url, **post_args)
  File "C:\Users\tobys\AppData\Roaming\Python\Python310\site-packages\requests\sessions.py", line 637, in post
    return self.request("POST", url, data=data, json=json, **kwargs)
  File "C:\Users\tobys\AppData\Roaming\Python\Python310\site-packages\requests\sessions.py", line 589, in request
    resp = self.send(prep, **send_kwargs)
  File "C:\Users\tobys\AppData\Roaming\Python\Python310\site-packages\requests\sessions.py", line 703, in send
    r = adapter.send(request, **kwargs)
  File "C:\Users\tobys\AppData\Roaming\Python\Python310\site-packages\requests\adapters.py", line 700, in send
    raise ConnectionError(e, request=request)
requests.exceptions.ConnectionError: HTTPSConnectionPool(host='api.wandb.ai', port=443): Max retries exceeded with url: /graphql (Caused by NameResolutionError("<urllib3.connection.HTTPSConnection object at 0x000001DB0DC46680>: Failed to resolve 'api.wandb.ai' ([Errno 11001] getaddrinfo failed)"))
